Workbook

Sheet Syn_Param
A1: MOF_Name | B1: Name | C1: Link_DOI | D1: CCDC_Link | E1: Uptake_Grav (wt. %) | F1: Uptake_Vol (g H2/L) | G1: Uptake Grav - Working Cap [%wt] | H1: Uptake Vol - Working Cap [g/L] | I1: Pressure (bar) | J1: Temperature (oC) | K1: Time (h) | L1: Yield | M1: Product (mg) | N1: Solvent_Name | O1: Solvent_Code | P1: Solvent_Volume (mL) | Q1: Additive_Name | R1: Additive_Code | S1: Additive_Volume (mL) | T1: Modulator_Name | U1: Modulator_Code | V1: Concentration (% or M) | W1: Modulator Sol_Volume (mL) | X1: Concentration (%w/w) | Y1: Modulator_Volume (mL) | Z1: Metal_Name | AA1: Metal_Code | AB1: Metal_Mass (mg) | AC1: Metal_Mol (mmol) | AD1: Linker1_Name | AE1: CAS1 | AF1: Norm_Name1 | AG1: Name1 | AH1: SMILES1 | AI1: Vendor_Name1 | AJ1: Max_Amount1 (g) | AK1: Min_Purity1 | AL1: Linker1_Mass (mg) | AM1: Linker1_Mol (mmol) | AN1: Linker2_Name | AO1: CAS2 | AP1: Norm_Name2 | AQ1: Name2 | AR1: SMILES2 | AS1: Vendor_Name2 | AT1: Max_Amount2 (g) | AU1: Min_Purity2 | AV1: Linker2_Mass (mg) | AW1: Linker2_Mol (mmol) | AX1: Linker1 (€/g) | AY1: Linker1 (€) | AZ1: Linker2 (€/g) | BA1: Linker2 (€)
A2: HUNCIE | B2: ZJU-31 | C2: http://dx.doi.org/10.1021/acs.cgd.5b00675 | D2: https://www.ccdc.cam.ac.uk/structures/Search?Ccdcid=HUNCIE&DatabaseToSearch=Published | E2: 13.69 | F2: 46.16 | G2: 13.110583 | H2: 43.382348 | I2: autogenous | J2: 80 | K2: 24 | L2: 0.5 | M2: =0.5*16.59 -> 8.295 | N2: DMA | O2: 1 | P2: 2 | Q2: H2O | R2: 10 | S2: 0.3 | T2: HNO3 | U2: 16 | V2: 0.65 | W2: =30/1000 -> 0.03 | X2: =V2 -> 0.65 | Y2: =W2*X2/Solvent!K17 -> 0.028676471 | Z2: Cu(NO₃)₂·2.5H₂O | AA2: 29 | AB2: =10 -> 10 | AC2: 0.0215 | AD2: (R)-H₄L | AE2: 1800290-01-0 | AF2: 4-[3-[4-[3,5-bis(4-carboxyphenyl)phenyl]-2,5-dimethoxyphenyl]-5-(4-carboxyphenyl)phenyl]benzoate | AG2: ["5',5''''-(2,5-Dimethoxy-1,4-phenylene)bis[1,1':3',1''-terphenyl]-4,4''-dicarboxylate"] | AH2: COC1=C(C=C(C(=C1)C=1C=C(C=C(C1)C1=CC=C(C=C1)C(=O)O)C1=CC=C(C=C1)C(=O)O)OC)C=1C=C(C=C(C1)C1=CC=C(C=C1)C(=O)O)C1=CC=C(C=C1)C(=O)O | AI2: BLD Pharm | AJ2: 1 | AK2: 0.98 | AL2: 5 | AM2: 0.0065 | AX2: 161.5 | AY2: 0.8075 | BA2: 0
A3: SUNLAP | C3: https://doi.org/10.1002/anie.200806227 | D3: https://www.ccdc.cam.ac.uk/structures/Search?Ccdcid=SUNLAP&DatabaseToSearch=Published | E3: 13.37 | F3: 46.97 | G3: 12.874313 | H3: 44.715887 | I3: autogenous | J3: 80 | K3: =2*7*24 -> 336 | L3: 0.42 | M3: 16.5 | N3: DMF | O3: 3 | P3: 3 | Q3: H2O | R3: 10 | S3: 1 | T3: NH3 | U3: 17 | V3: 3 | W3: 0.6 | X3: =V3*17.3/(0.9*1000) -> 0.057666667 | Y3: =W3*X3/Solvent!K18 -> 0.1384 | Z3: Cu(NO₃)₂·2.5H₂O | AA3: 29 | AB3: 40 | AC3: 0.17 | AD3: (R)-H₄L | AG3: 2,2'-Diethoxy-1,1'-binaphthalene-4,4',6,6'-tetrabenzoate | AH3: C(C)OC1=C(C2=CC=C(C=C2C(=C1)C1=CC=CC=C1C(=O)O)C1=CC=CC=C1C(=O)O)C1=C(C=C(C2=CC(=CC=C12)C1=CC=CC=C1C(=O)O)C1=CC=CC=C1C(=O)O)OCC | AL3: 20 | AM3: 0.024 | AY3: 0 | BA3: 0
A4: VETMIS | C4: http://dx.doi.org/10.1002/chem.201203093 | D4: https://www.ccdc.cam.ac.uk/structures/Search?Ccdcid=VETMIS&DatabaseToSearch=Published | E4: 13.27 | F4: 47.75 | G4: 12.629085 | H4: 44.990621 | I4: autogenous | J4: =358-273 -> 85 | K4: 72 | L4: 0.78 | M4: =(0.1*3*(62*12+91*1+63.5+9*14+13*16))*0.78 -> 288.405 | N4: DMA | O4: 1 | P4: 5 | T4: HBF4 | U4: 18 | V4: 0.48 | W4: 0.2 | X4: =V4 -> 0.48 | Y4: =X4*W4/(Solvent!K19) -> 0.096969697 | Z4: Cu(NO₃)₂·3H₂O | AA4: 30 | AB4: =0.121*1000 -> 121 | AC4: 0.5 | AD4: H₆L | AG4: 6,6',6'',6'''-((5'-(4-(bis(6-carboxynaphthalen-2-yl)amine)phenyl)-[1,1':3',1''-terphenyl]-4,4''-diyl)bis(azanetri-yl))-tetrakis(2-naphthoate) | AH4: C(=O)(O)C=1C=C2C=CC(=CC2=CC1)N(C1=CC=C(C=C1)C=1C=C(C=C(C1)C1=CC=C(C=C1)N(C=1C=C2C=CC(=CC2=CC1)C(=O)O)C=1C=C2C=CC(=CC2=CC1)C(=O)O)C1=CC=C(C=C1)N(C=1C=C2C=CC(=CC2=CC1)C(=O)O)C=1C=C2C=CC(=CC2=CC1)C(=O)O)C1=CC2=CC=C(C=C2C=C1)C(=O)O | AL4: =0.137*1000 -> 137 | AM4: 0.1 | AY4: 0 | BA4: 0
A5: BAZFUF | C5: http://dx.doi.org/10.1021/ic201376t | D5: https://www.ccdc.cam.ac.uk/structures/Search?Ccdcid=BAZFUF&DatabaseToSearch=Published | E5: 12.5 | F5: 48.58 | G5: 11.69857 | H5: 45.06427 | I5: autogenous | J5: 85 | K5: 48 | L5: 0.26 | M5: 18.6 | N5: DMF | O5: 3 | P5: 5 | Q5: NMP | R5: 5 | S5: 5 | Z5: Cu(NO₃)₂·2.5H₂O | AA5: 29 | AB5: 33.3 | AC5: 0.143 | AD5: H₃BBC | AE5: 50446-44-1 | AF5: 1,3,5-tris(4-Carboxyphenyl)benzene | AG5: ["1,3,5-tris(4-Carboxyphenyl)benzene", "1,3,5-tris(4-carboxylatephenyl)benzene", "benzene-1,3,4-tribenzoate", "4,4',4''-benzene-1,3,5-tribenzoate"] | AH5: C(=O)(O)C1=CC=C(C=C1)C1=CC(=CC(=C1)C1=CC=C(C=C1)C(=O)O)C1=CC=C(C=C1)C(=O)O | AI5: XtalPi Inc | AJ5: 25 | AK5: 0.99 | AL5: 30.4 | AM5: 0.046 | AX5: 6.868 | AY5: 0.2087872 | BA5: 0
A6: BAZFUF01 | B6: DUT-23(Cu) | C6: http://dx.doi.org/10.1002/chem.201101383 | D6: https://www.ccdc.cam.ac.uk/structures/Search?Ccdcid=BAZFUF&DatabaseToSearch=Published | E6: 12.44 | F6: 48.6 | G6: 11.653757 | H6: 44.89563 | I6: autogenous | J6: =353-273 -> 80 | K6: 20 | L6: =29% -> 0.29 | M6: =L6*109 -> 31.61 | N6: DMF | O6: 3 | P6: 5 | Q6: EtOH | R6: 12 | S6: 5 | Z6: Cu(NO₃)₂·3H₂O | AA6: 30 | AB6: 241 | AC6: 1 | AD6: H3(btb) | AE6: 955050-88-1 | AF6: benzene-1,3,5-tribenzoate | AG6: ["benzene-1,3,5-tribenzoate", "1,3,5-benzenetribenzoate"] | AH6: C1(=CC(=CC(=C1)C1=CC=CC=C1C(=O)O)C1=CC=CC=C1C(=O)O)C1=CC=CC=C1C(=O)O | AI6: Manchester Organics | AJ6: 5 | AK6: 0.9 | AL6: 109 | AM6: 0.25 | AN6: bipy | AP6: 4,4′-bipyridine | AV6: 42 | AW6: 0.27 | AX6: 48.28 | AY6: 5.26252 | AZ6: 0.2907 | BA6: 0.0122094
A7: OMUSAS | B7: truMOF-2 | C7: http://dx.doi.org/10.1021/jacs.6b01345 | D7: https://www.ccdc.cam.ac.uk/structures/Search?Ccdcid=OMUSAS&DatabaseToSearch=Published | E7: 11.75 | F7: 42.34 | G7: 11.626265 | H7: 44.343849 | I7: autogenous | J7: 90 | K7: 48 | L7: =50% -> 0.5 | M7: =50.8*L7 -> 25.4 | N7: DMF | O7: 3 | P7: 10 | Q7: MeOH | R7: 11 | S7: 0.3 | Z7: Zn(NO₃)₂·4H₂O | AA7: 44 | AB7: 60 | AD7: H₃L | AG7: 4,4',4''-(5,5,10,10,15,15-hexaethyl-10,15-dihydro-5H-diindeno[1,2-a:1',2'-c]fluorene-2,7,12-triyl)tribenzoate | AH7: C(C)C1(C2=CC(=CC=C2C=2C1=C1C(=C3C=4C=CC(=CC4C(C23)(CC)CC)C2=CC=C(C(=O)O)C=C2)C(C2=CC(=CC=C21)C2=CC=C(C(=O)O)C=C2)(CC)CC)C2=CC=C(C(=O)O)C=C2)CC | AL7: 45 | AY7: 0 | BA7: 0
A8: OWIZAW | B8: MOF-4 | C8: http://dx.doi.org/10.1021/ic1009169 | D8: https://www.ccdc.cam.ac.uk/structures/Search?Ccdcid=OWIZAW&DatabaseToSearch=Published | E8: 11.43 | F8: 48.88 | G8: 10.802115 | H8: 46.293327 | I8: autogenous | J8: 80 | K8: 48 | L8: 0.187 | M8: 8.5 | N8: DEF | O8: 4 | P8: 7 | Q8: H2O | R8: 10 | S8: 1 | T8: HCl | U8: 19 | V8: 3 | W8: =50/1000 -> 0.05 | X8: =V8*36.46/(1.18*1000) -> 0.092694915 | Y8: =W8*X8/Solvent!K20 -> 0.012874294 | Z8: Cu(NO3)2·2.5H2O | AA8: 29 | AB8: 20 | AC8: 0.085 | AD8: L4-H4 | AG8: 4,4',4'',4'''-(Methanetetrayltetrakis(benzene-4,1-diylethyne-2,1-diyl))tetrabenzoate | AH8: C(C1=CC=C(C=C1)C#CC1=CC=C(C(=O)O)C=C1)(C1=CC=C(C=C1)C#CC1=CC=C(C(=O)O)C=C1)(C1=CC=C(C=C1)C#CC1=CC=C(C(=O)O)C=C1)C1=CC=C(C=C1)C#CC1=CC=C(C(=O)O)C=C1 | AL8: 10 | AM8: 0.011 | AY8: 0 | BA8: 0
A9: ADATIK | B9: MOF-8 | C9: http://dx.doi.org/10.1002/anie.201201202 | D9: https://www.ccdc.cam.ac.uk/structures/Search?Ccdcid=ADATIK&DatabaseToSearch=Published | E9: 11.31 | F9: 48.15 | G9: 10.683085 | H9: 44.766191 | I9: autogenous | J9: =(75+85)/2 -> 80 | K9: =20+12 -> 32 | L9: 0.5 | M9: =78.7*L9 -> 39.35 | N9: DMF | O9: 3 | P9: 1 | Z9: Cu(NO3)2·2.5H2O | AA9: 29 | AB9: 39.1 | AC9: 0.168 | AD9: H₃L4 | AG9: 5'-(4-(1H-tetrazol-5-yl)benzamide)benzene-1,3-dioate | AH9: N=1NN=NC1C1=CC=C(C(=O)NC=2C=C(C=C(C2)C(=O)O)C(=O)O)C=C1 | AL9: 39.6 | AM9: 0.112 | AY9: 0 | BA9: 0
A10: MEHMET | B10: NU-111 | C10: http://dx.doi.org/10.1021/ja302623w | D10: https://www.ccdc.cam.ac.uk/structures/Search?Ccdcid=MEHMET&DatabaseToSearch=Published | E10: 10.71 | F10: 49.02 | G10: 9.9162715 | H10: 45.200664 | I10: autogenous | J10: 80 | K10: 48 | L10: 0.75 | M10: 535.5 | N10: DMF | O10: 3 | P10: 75 | Q10: EtOH | R10: 12 | S10: 75 | T10: HCl | U10: 19 | V10: 3 | W10: 1.4 | X10: =V10*36.46/(1.18*1000) -> 0.092694915 | Y10: =W10*X10/Solvent!K20 -> 0.36048023 | Z10: Cu(NO₃)₂·2.5H₂O | AA10: 29 | AB10: 900 | AC10: 3.87 | AD10: LH₆(3) | AG10: 1,3,5-tris(4-(3,5-Dicarboxylatephenyl)buta-1,3-diyn-1-yl)benzene | AH10: C(=O)(O)C=1C=C(C=C(C1)C(=O)O)C#CC#CC1=CC(=CC(=C1)C#CC#CC1=CC(=CC(=C1)C(=O)O)C(=O)O)C#CC#CC1=CC(=CC(=C1)C(=O)O)C(=O)O | AL10: 300 | AM10: 0.42 | AY10: 0 | BA10: 0
A11: YIPDOR | B11: 1 | C11: http://dx.doi.org/10.1039/b709563e | D11: https://www.ccdc.cam.ac.uk/structures/Search?Ccdcid=YIPDOR&DatabaseToSearch=Published | E11: 10.7 | F11: 53.73 | G11: 9.4914341 | H11: 47.700088 | I11: autogenous | J11: 140 | K11: =5*24 -> 120 | L11: 0.52 | M11: 86 | N11: H2O | O11: 10 | P11: 10 | T11: H3PMo12O40 | U11: 20 | W11: 91 | Y11: =W11 -> 91 | Z11: Cu(NO₃)₂·3H₂O | AA11: 30 | AB11: 36 | AC11: 0.15 | AD11: L | AE11: 7664-38-2 | AF11: phosphate | AG11: ["dihydrogen_phosphate", "phosphito", "Hydrogenphosphate", "phosphate"] | AH11: P(=O)(O)(O)O | AI11: ABCR | AJ11: 17000 | AK11: 0.85 | AL11: 158 | AM11: 0.5 | AX11: 0.01474706 | AY11: 0.0023300355 | BA11: 0
A12: PODKUQ | C12: http://dx.doi.org/10.1021/cm404155s | D12: https://www.ccdc.cam.ac.uk/structures/Search?Ccdcid=PODKUQ&DatabaseToSearch=Published | E12: 10.6 | F12: 50.49 | G12: 9.6966161 | H12: 46.240975 | I12: autogenous | J12: 80 | K12: 24 | L12: 0.52 | M12: 160.14 | N12: DMF | O12: 3 | P12: 10 | T12: HBF4 | U12: 18 | V12: 0.48 | W12: 3 | X12: =V12 -> 0.48 | Y12: =W12*X12/Solvent!K19 -> 1.4545455 | Z12: Cu(NO₃)₂·2.5H₂O | AA12: 29 | AB12: 250 | AC12: 1.1 | AD12: L4 | AG12: 1,3,5-tris(4-(1-(3,5-dicarboxylatephenyl)-1,2,3-triazol-4-yl)phenyl)phenyl | AH12: C(=O)(O)C=1C=C(C=C(C1)C(=O)O)N1N=NC(=C1)C1=CC=C(C=C1)[C]1CC(=CC(=C1)C1=CC=C(C=C1)C=1N=NN(C1)C1=CC(=CC(=C1)C(=O)O)C(=O)O)C1=CC=C(C=C1)C=1N=NN(C1)C1=CC(=CC(=C1)C(=O)O)C(=O)O | AL12: 260 | AM12: 0.26 | AY12: 0 | BA12: 0
A13: GUHMIH | C13: http://dx.doi.org/10.1039/C5RA06204G | D13: https://www.ccdc.cam.ac.uk/structures/Search?Ccdcid=GUHMIH&DatabaseToSearch=Published | E13: 10.35 | F13: 57.54 | G13: 8.6913484 | H13: 49.550824 | I13: autogenous | J13: 120 | K13: =4*24 -> 96 | L13: 0.3 | M13: 100.3 | N13: H2O | O13: 10 | P13: 10 | T13: HCl | U13: 19 | V13: 1 | W13: 0.5 | X13: =V13*36.46/(1.18*1000) -> 0.030898305 | Y13: =W13*X13/Solvent!K20 -> 0.042914313 | Z13: CuSO₄·5H₂O | AA13: 33 | AB13: =0.12*1000 -> 120 | AC13: 0.48 | AD13: 3-dpye | AE13: 49807-92-3 | AF13: 1,2-bis(3-Pyridinecarboxamido)ethane | AG13: ["N,N'-ethane-1,2-diyldinico", "1,2-bis(3-Pyridinecarboxamide)ethane"] | AH13: N1=CC(=CC=C1)C(=O)NCCNC(=O)C=1C=NC=CC1 | AI13: Ochem Incorporation | AJ13: 5 | AK13: 0.99 | AL13: =0.04*1000 -> 40 | AM13: 0.15 | AN13: K₆P₂W₁₈O₆₂·15H₂O | AO13: 7664-38-2 | AP13: phosphate | AQ13: ["dihydrogen_phosphate", "phosphito", "Hydrogenphosphate", "phosphate"] | AR13: P(=O)(O)(O)O | AS13: Oakwood Chemical | AT13: 3000 | AU13: 0.85 | AV13: =0.3*1000 -> 300 | AW13: 0.06 | AX13: 191.25 | AY13: 7.65 | AZ13: 0.043066667 | BA13: 0.01292
A14: WAGQAY | C14: http://dx.doi.org/10.1002/anie.201001735 | D14: https://www.ccdc.cam.ac.uk/structures/Search?Ccdcid=WAGQAY&DatabaseToSearch=Published | E14: 10.13 | F14: 44.16 | G14: 9.792664 | H14: 42.418753 | I14: autogenous | J14: 120 | K14: 20 | L14: 0.54 | M14: 412 | N14: DEF | O14: 4 | P14: 10.5 | Z14: Ni(NO₃)₂·6H₂O | AA14: 48 | AB14: 366 | AC14: 1.26 | AD14: H₃btb | AE14: 50446-44-1 | AF14: 1,3,5-tris(4-Carboxyphenyl)benzene | AG14: ["4,4',4''-Benzene-1,3,5-triyltris(benzoate)", "4,4',4''-(benzene-1,3,5-triyl)tribenzoateo", "4,4',4''-benzene-1,3,5-triylbenzoate", "4,4',4''-Benzene-1,3,5-triyltribenzoate", "benzene-1,3,5-tris(4-benzoate)", "4,4',4''-(1,3,5-triphenylene)-tribenzoate", "1,3,5-tris(4-Carbxoylatephenyl)benzene", "4,4',4''-(Benzene-1,3,5-triyl)tribenzoate", "Benzene-1,3,5-tris(phenyl-4-carboxylate)", "(Benzene-1,3,5-triyl)-4,4',4''-tribenzoate", "Benzene-1,3,5-tris(4-benzoate)"] | AH14: C1(=CC(=CC(=C1)C1=CC=C(C(=O)O)C=C1)C1=CC=C(C(=O)O)C=C1)C1=CC=C(C(=O)O)C=C1 | AI14: XtalPi Inc | AJ14: 100 | AK14: 0.95 | AL14: 180 | AM14: 0.41 | AX14: 6.8765 | AY14: 1.23777 | BA14: 0
A15: ADASEF | B15: MOF-3 | C15: http://dx.doi.org/10.1002/anie.201201202 | D15: https://www.ccdc.cam.ac.uk/structures/Search?Ccdcid=ADASEF&DatabaseToSearch=Published | E15: 10.07 | F15: 48.8 | G15: 9.4758231 | H15: 45.836878 | I15: autogenous | J15: 75 | K15: 40 | L15: 0.5 | M15: =40*L15 -> 20 | N15: DMF | O15: 3 | P15: 1 | Z15: Cu(NO₃)₂·2.5H₂O | AA15: 29 | AB15: 39.1 | AC15: 0.168 | AD15: H3L₃ | AE15: 1159595-96-6 | AF15: 5-[4-(2H-tetrazol-5-yl)phenyl]benzene-1,3-dicarboxylate | AG15: ["4'-(1H-tetrazol-5-yl)biphenyl-3,5-dicarboxylate"] | AH15: N1N=NN=C1C1=CC=C(C=C1)C1=CC(=CC(=C1)C(=O)O)C(=O)O | AI15: Accela ChemBio | AJ15: 1 | AK15: 0.99 | AL15: 36.2 | AM15: 0.112 | AX15: 1606.5 | AY15: 58.1553 | BA15: 0
A16: EPOTAF | B16: SNU-21 | C16: http://dx.doi.org/10.1039/c0cc05199c | D16: https://www.ccdc.cam.ac.uk/structures/Search?Ccdcid=EPOTAF&DatabaseToSearch=Published | E16: 9.4 | F16: 59.69 | G16: 7.8333954 | H16: 50.274727 | I16: autogenous | J16: 80 | K16: 24 | L16: 0.47 | M16: 40 | N16: DMF | P16: 6 | Q16: MeOH | R16: 11 | S16: 1 | T16: HCl | U16: 19 | V16: 0.35 | W16: =0.5 -> 0.5 | X16: =V16 -> 0.35 | Y16: =W16*X16/Solvent!K20 -> 0.48611111 | Z16: Cu(NO₃)₂·2.5H₂O | AA16: 29 | AB16: =0.025*1000 -> 25 | AC16: 0.11 | AD16: H4TCM | AE16: 245551-35-3 | AF16: 4,4'-[{2,2-bis[(4-carboxylatophenoxy)methyl]propane-1,3-diyl}bis(oxy)]dibenzoate | AG16: ["4-(3-(4-Carboxylatephenoxy)-2,2-bis((4-carboxyphenoxy)methyl)propoxy)benzoate", "4-(3-(4-carboxylatephenoxy)-2,2-bis((4-carboxyphenoxy)methyl)propoxy)benzoate", "4-(3-(4-carboxylatephenoxy)-2,2-bis[(4-carboxylatephenoxy)methyl]propoxy)benzoate", "tetrakis[4-(carboxylatephenoxy)methyl]methane", "4-(3-(4-Carboxyphenoxy)-2,2-bis((4-carboxyphenoxy)methyl)propoxy)benzoate"] | AH16: C(=O)(O)C1=CC=C(OCC(COC2=CC=C(C(=O)O)C=C2)(COC2=CC=C(C=C2)C(=O)O)COC2=CC=C(C=C2)C(=O)O)C=C1 | AI16: XtalPi Inc | AJ16: 5 | AK16: 0.97 | AL16: =0.033*1000 -> 33 | AM16: 0.054 | AX16: 140.25 | AY16: 4.62825 | BA16: 0
A17: FAGQAI | B17: TCM-10 | C17: http://dx.doi.org/10.1002/ejic.201501194 | D17: https://www.ccdc.cam.ac.uk/structures/Search?Ccdcid=FAGQAI&DatabaseToSearch=Published | E17: 9.3 | F17: 49.32 | G17: 8.6144276 | H17: 45.71067 | I17: autogenous | J17: 85 | K17: 48 | L17: 0.1 | M17: 11.79 | N17: DMF | O17: 3 | P17: 2.25 | Z17: Cu(NO₃)₂·3H₂O | AA17: 30 | AB17: =0.065*1000 -> 65 | AC17: 0.27 | AD17: BTEB (C₃₀H₁₅O₆) | AE17: 205383-17-1 | AF17: 4,4',4''-(Benzene-1,3,5-triyltriethyne-2,1-diyl)tribenzoate | AG17: ["4,4',4''-(Benzene-1,3,5-triyltriethyne-2,1-diyl)tribenzoate", "1,3,5-tris((4-carboxylatephenyl)ethynyl)benzene", "benzene-1,3,5-triyl-tris(ethyne-2,1-diyl)]tribenzoate", "4,4',4''-[benzene-1,3,5-triyl-tris(ethyne-2,1-diyl)]tribenzoate", "4,4',4''-(benzene-1,3,5-triyl-tris(ethyne-2,1-diyl)tribenzoate)"] | AH17: C1(=CC(=CC(=C1)C#CC1=CC=C(C(=O)O)C=C1)C#CC1=CC=C(C(=O)O)C=C1)C#CC1=CC=C(C(=O)O)C=C1 | AI17: XtalPi Inc | AJ17: 5 | AK17: 0.98 | AL17: =0.094*1000 -> 94 | AN17: bipy | AP17: 4,4′-bipyridine | AV17: =0.015*1000 -> 15 | AX17: 134.81 | AY17: 12.67214 | AZ17: 0.2907 | BA17: 0.0043605
A18: DICKEH | B18: NJU-Bai12 | C18: http://dx.doi.org/10.1021/ic302018g | D18: https://www.ccdc.cam.ac.uk/structures/Search?Ccdcid=DICKEH&DatabaseToSearch=Published | E18: 9.27 | F18: 53.4 | G18: 8.3209692 | H18: 47.546346 | I18: autogenous | J18: 65 | K18: 72 | L18: 0.73 | M18: 11.2 | N18: DMF | O18: 3 | P18: 2 | Q18: H2O | R18: 10 | S18: 0.1 | T18: HBF4 | U18: 18 | V18: 0.48 | W18: =50/1000 -> 0.05 | X18: =V18 -> 0.48 | Y18: =W18*X18/Solvent!K19 -> 0.024242424 | Z18: CuCl₂·2H₂O | AA18: 34 | AB18: 17 | AC18: 0.1 | AD18: PDEB | AE18: 957014-40-3 | AF18: 5-[2-[4-[2-(3,5-dicarboxyphenyl)ethynyl]phenyl]ethynyl]benzene-1,3-dicarboxylate | AG18: ["5,5'-(1,4-Phenylenediethyne-2,1-diyl)diisophthalate"] | AH18: C1(=CC=C(C=C1)C#CC=1C=C(C=C(C(=O)O)C1)C(=O)O)C#CC=1C=C(C=C(C(=O)O)C1)C(=O)O | AI18: XtalPi Inc | AJ18: 1 | AK18: 0.97 | AL18: 11.33 | AM18: =0.025 -> 0.025 | AX18: 130.9 | AY18: 1.483097 | BA18: 0
A19: BINSAU | C19: http://dx.doi.org/10.1021/ic401870e | D19: https://www.ccdc.cam.ac.uk/structures/Search?Ccdcid=BINSAU&DatabaseToSearch=Published | E19: 9.23 | F19: 47.96 | G19: 8.5335743 | H19: 44.262172 | I19: autogenous | J19: 100 | K19: =7*24 -> 168 | L19: 0.23 | M19: 6.1 | N19: DMF | O19: 3 | P19: 1.5 | Z19: Mn(NO₃)₂·4H₂O | AA19: 50 | AB19: 25 | AC19: =99.6/1000 -> 0.0996 | AD19: H₃BTN | AE19: 138916-83-3 | AF19: 6-[3,5-bis(6-carboxynaphthalen-2-yl)phenyl]naphthalene-2-carboxylate | AG19: ["6,6',6''-Benzene-1,3,5-triyltrinaphthalene-2-carboxylate", "6,6',6''-benzene-1,3,5-triyltri(2-naphthoate)", "6',6''-benzene-1,3,5-triyltri(naphthalene-2-carboxylate)", "6,6',6''-Benzene-1,3,5-triyltris(2-naphthoate)"] | AH19: C1(=CC(=CC(=C1)C=1C=C2C=CC(=CC2=CC1)C(=O)O)C=1C=C2C=CC(=CC2=CC1)C(=O)O)C=1C=C2C=CC(=CC2=CC1)C(=O)O | AI19: BLD Pharmatech GmbH | AJ19: 5 | AK19: 0.95 | AL19: 10 | AM19: =17.1/1000 -> 0.0171 | AX19: 141.61 | AY19: 1.4161 | BA19: 0
A20: WIJXIY | C20: http://dx.doi.org/10.1016/j.jssc.2013.08.026 | D20: https://www.ccdc.cam.ac.uk/structures/Search?Ccdcid=WIJXIY&DatabaseToSearch=Published | E20: 9.09 | F20: 47.51 | G20: 8.7003324 | H20: 46.462115 | I20: autogenous | J20: 85 | K20: 16 | L20: 0.5 | M20: 23.2 | N20: DEF | O20: 4 | P20: 3 | Z20: Zn(NO₃)₂·6H₂O | AA20: 45 | AB20: =0.15*1000 -> 150 | AC20: =0.6 -> 0.6 | AD20: 2,7-H₂CDC | AE20: 1409971-87-4 | AF20: 9H-carbazole-2,7-dicarboxylate | AG20: ["9H-Carbazole-2,7-dicarboxylate"] | AH20: C1=C(C=CC=2C3=CC=C(C=C3NC12)C(=O)O)C(=O)O | AI20: XtalPi Inc | AJ20: 1 | AK20: 0.95 | AL20: =0.026*1000 -> 26 | AM20: =0.1 -> 0.1 | AX20: 76.67 | AY20: 1.99342 | BA20: 0
A21: BINROH | B21: UTSA-28-Cu | C21: http://dx.doi.org/10.1021/ic401870e | D21: https://www.ccdc.cam.ac.uk/structures/Search?Ccdcid=BINROH&DatabaseToSearch=Published | E21: 8.82 | F21: 48.75 | G21: 8.1723518 | H21: 44.615404 | I21: autogenous | J21: 90 | K21: 24 | L21: 0.71 | M21: 16.49 | N21: DEF | O21: 4 | P21: 1 | Q21: H2O | R21: 10 | S21: 0.1 | T21: HCl | U21: 19 | V21: 6 | W21: =10/1000 -> 0.01 | X21: =V21*36.46/(1.18*1000) -> 0.18538983 | Y21: =W21*X21/Solvent!K20 -> 0.0051497175 | Z21: Cu(NO₃)₂·2.5H₂O | AA21: 29 | AB21: =14.5 -> 14.5 | AC21: =62.3/1000 -> 0.0623 | AD21: H₃BTN | AE21: 138916-83-3 | AF21: 6-[3,5-bis(6-carboxynaphthalen-2-yl)phenyl]naphthalene-2-carboxylate | AG21: ["6,6',6''-Benzene-1,3,5-triyltrinaphthalene-2-carboxylate", "6,6',6''-benzene-1,3,5-triyltri(2-naphthoate)", "6',6''-benzene-1,3,5-triyltri(naphthalene-2-carboxylate)", "6,6',6''-Benzene-1,3,5-triyltris(2-naphthoate)"] | AH21: C1(=CC(=CC(=C1)C=1C=C2C=CC(=CC2=CC1)C(=O)O)C=1C=C2C=CC(=CC2=CC1)C(=O)O)C=1C=C2C=CC(=CC2=CC1)C(=O)O | AI21: BLD Pharmatech GmbH | AJ21: 5 | AK21: 0.95 | AL21: =8.3 -> 8.3 | AM21: =14.2/1000 -> 0.0142 | AX21: 150.11 | AY21: 1.245913 | BA21: 0
A22: HOVQAM | C22: http://dx.doi.org/10.1016/j.poly.2015.01.039 | D22: https://www.ccdc.cam.ac.uk/structures/Search?Ccdcid=HOVQAM&DatabaseToSearch=Published | E22: 8.69 | F22: 59.44 | G22: 6.8024417 | H22: 47.741018 | I22: atmosferik/terbuka | J22: 29 | K22: =14*24 -> 336 | L22: 0.49 | M22: 25.97 | N22: CH2CL2 | O22: 27 | P22: 6 | Q22: MeOH | R22: 11 | S22: 6 | T22: NaOH | U22: 9 | W22: 0.5 | Y22: =W22 -> 0.5 | Z22: Co(ClO₄)₂·6H₂O | AA22: 42 | AB22: =0.018*1000 -> 18 | AC22: =0.05 -> 0.05 | AD22: HL | AG22: 1-(imidazol-1-yl)-4-(imidazol-4-yl)benzene | AH22: N1(C=NC=C1)C1=CC=C(C=C1)C=1N=CNC1 | AL22: =0.011*1000 -> 11 | AM22: =0.05 -> 0.05 | AY22: 0 | BA22: 0
A23: GAHWIX | C23: http://dx.doi.org/10.1039/c0nj00272k | D23: https://www.ccdc.cam.ac.uk/structures/Search?Ccdcid=GAHWIX&DatabaseToSearch=Published | E23: 8.67 | F23: 55.97 | G23: 7.4703409 | H23: 48.114515 | I23: atmosferik/terbuka | J23: 95 | K23: 24 | L23: 0.83 | M23: 33 | N23: DMF | O23: 3 | P23: 10 | Z23: Zn(NO3)2·6H2O | AA23: 45 | AB23: 61.6 | AC23: =0.206 -> 0.206 | AD23: H3L3H2O | AE23: 120360-51-2 | AF23: 4-[[3,5-bis[(4-carboxyphenyl)carbamoyl]benzoyl]amino]benzoate | AG23: ["4,4',4''-(benzene-1,3,5-triyltris(carbonylimino))tribenzoate", "4,4',4''-[1,3,5-benzenetriyltris(carbonylimino)]tribenzoate"] | AH23: C1(=CC(=CC(=C1)C(=O)NC1=CC=C(C(=O)O)C=C1)C(=O)NC1=CC=C(C(=O)O)C=C1)C(=O)NC1=CC=C(C(=O)O)C=C1 | AI23: XtalPi Inc | AJ23: 1 | AK23: 0.99 | AL23: 28.4 | AM23: 0.0457 | AX23: 219.3 | AY23: 6.22812 | BA23: 0
A24: ANUGOG | B24: UMCM-153 | C24: http://dx.doi.org/10.1021/ja107423k | D24: https://www.ccdc.cam.ac.uk/structures/Search?Ccdcid=ANUGOG&DatabaseToSearch=Published | E24: 8.6 | F24: 54.99 | G24: 7.5877322 | H24: 47.895646 | I24: atmosferik/terbuka | J24: 85 | K24: 12 | L24: 0.8 | M24: 64.57 | N24: DMF | O24: 3 | P24: =(4/6)*10 -> 6.6666667 | Q24: H2O | R24: 10 | S24: =(1/6)*10 -> 1.6666667 | T24: Dioxane | U24: 25 | W24: =S24 -> 1.6666667 | Y24: =W24 -> 1.6666667 | Z24: Cu(NO3)2 · 2.5H2O | AA24: 29 | AB24: =0.096*1000 -> 96 | AC24: =0.41 -> 0.41 | AD24: (H2) | AE24: 1250980-04-1 | AF24: 5-[3,5-bis(4-carboxyphenyl)phenyl]benzene-1,3-dicarboxylate | AG24: ["5-(3,5-bis(4-carboxyphenyl)phenyl)benzene-1,3-dicarboxylate"] | AH24: C(=O)(O)C1=CC=C(C=C1)C=1C=C(C=C(C1)C1=CC=C(C=C1)C(=O)O)C=1C=C(C=C(C1)C(=O)O)C(=O)O | AI24: XtalPi Inc | AJ24: 1 | AK24: 0.98 | AL24: =0.05*1000 -> 50 | AM24: =0.14 -> 0.14 | AX24: 158.1 | AY24: 7.905 | BA24: 0
A25: ANUGIA | B25: UMCM-152 | C25: http://dx.doi.org/10.1021/ja107423k | D25: https://www.ccdc.cam.ac.uk/structures/Search?Ccdcid=ANUGIA&DatabaseToSearch=Published | E25: 8.59 | F25: 53.35 | G25: 7.6307646 | H25: 47.319262 | I25: atmosferik/terbuka | J25: 85 | K25: 12 | L25: 0.82 | M25: 51.85 | N25: DMF | O25: 3 | P25: =(4/6)*10 -> 6.6666667 | Q25: H2O | R25: 10 | S25: =(1/6)*10 -> 1.6666667 | T25: Dioxane | U25: 25 | W25: =S25 -> 1.6666667 | Y25: =W25 -> 1.6666667 | Z25: Cu(NO3)2 · 2.5H2O | AA25: 29 | AB25: =0.096*1000 -> 96 | AC25: =0.41 -> 0.41 | AD25: (H43) | AE25: 1250980-04-1 | AF25: 5-[3,5-bis(4-carboxyphenyl)phenyl]benzene-1,3-dicarboxylate | AG25: ["5-(3,5-bis(4-carboxyphenyl)phenyl)benzene-1,3-dicarboxylate"] | AH25: C(=O)(O)C1=CC=C(C=C1)C=1C=C(C=C(C1)C1=CC=C(C=C1)C(=O)O)C=1C=C(C=C(C1)C(=O)O)C(=O)O | AI25: XtalPi Inc | AJ25: 1 | AK25: 0.98 | AL25: =0.05*1000 -> 50 | AM25: =0.1 -> 0.1 | AX25: 158.1 | AY25: 7.905 | BA25: 0
A26: LIKDOA | B26: ZJU-36 | C26: http://dx.doi.org/10.1002/chem.201302515 | D26: https://www.ccdc.cam.ac.uk/structures/Search?Ccdcid=LIKDOA&DatabaseToSearch=Published | E26: 8.55 | F26: 50.16 | G26: 7.9363083 | H26: 46.548221 | I26: atmosferik/terbuka | J26: 65 | K26: 48 | L26: 0.75 | M26: 30.47 | N26: DMF | O26: 3 | P26: 20 | Q26: H2O | R26: 10 | S26: 12 | T26: HCl | U26: 19 | V26: 0.1 | W26: 2.8 | X26: =V26*36.46/(1.18*1000) -> 0.0030898305 | Y26: =W26*X26/Solvent!K20 -> 0.024032015 | Z26: Cu(NO3)2·3H2O | AA26: 30 | AB26: 40 | AC26: =0.17 -> 0.17 | AD26: H₃L₁ | AG26: 3,5-bis(2-carboxylateethenyl)benzoate | AH26: C(=O)(O)C=CC=1C=C(C(=O)O)C=C(C1)C=CC(=O)O | AL26: 20 | AM26: =0.085 -> 0.085 | AY26: 0 | BA26: 0
A27: PELRIJ | C27: http://dx.doi.org/10.1039/c2ce26015h | D27: https://www.ccdc.cam.ac.uk/structures/Search?Ccdcid=PELRIJ&DatabaseToSearch=Published | E27: 8.54 | F27: 48.29 | G27: 7.9261389 | H27: 44.833195 | I27: autogenous | J27: 70 | K27: 48 | L27: 0.91 | M27: =0.106*1000 -> 106 | N27: DMF | O27: 3 | P27: 4 | T27: HNO3 | U27: 16 | V27: 1 | W27: =0.7 -> 0.7 | X27: =V27*63.02/(1.42*1000) -> 0.044380282 | Y27: =W27*X27/Solvent!K17 -> 0.045685584 | Z27: Cu(NO₃)₂·6H₂O | AA27: 32 | AB27: =0.034*1000 -> 34 | AC27: =0.16 -> 0.16 | AD27: H₃L₁ | AE27: 120360-51-2 | AF27: 4-[[3,5-bis[(4-carboxyphenyl)carbamoyl]benzoyl]amino]benzoate | AG27: ["4,4',4''-(benzene-1,3,5-triyltris(carbonylimino))tribenzoate", "4,4',4''-[1,3,5-benzenetriyltris(carbonylimino)]tribenzoate"] | AH27: C1(=CC(=CC(=C1)C(=O)NC1=CC=C(C(=O)O)C=C1)C(=O)NC1=CC=C(C(=O)O)C=C1)C(=O)NC1=CC=C(C(=O)O)C=C1 | AI27: XtalPi Inc | AJ27: 1 | AK27: 0.99 | AL27: =0.049*1000 -> 49 | AM27: =0.08 -> 0.08 | AX27: 219.3 | AY27: 10.7457 | BA27: 0
A28: XAVKIR | B28: HHU-1 | C28: http://dx.doi.org/10.1039/C6QI00616G | D28: https://www.ccdc.cam.ac.uk/structures/Search?Ccdcid=XAVKIR&DatabaseToSearch=Published | E28: 8.28 | F28: 48.24 | G28: 7.7455366 | H28: 44.768125 | I28: autogenous | J28: 55 | K28: =5*24 -> 120 | L28: 0.506 | M28: 14.81 | N28: DMF | O28: 3 | P28: =(5/6)*2 -> 1.6666667 | Q28: H2O | R28: 10 | S28: =(1/6)*2 -> 0.33333333 | Z28: Cu(NO₃)₂·3H₂O | AA28: 30 | AB28: =19.3 -> 19.3 | AC28: =0.08 -> 0.08 | AD28: H₄PANAD | AG28: 5,5'-[pyridine-3,5-diylbis(carbonyliminonaphthalene-6,2-diylcarbonylimino)]bis(benzene-1,3-dicarboxylate) | AH28: O=C(Nc1cc2ccc(cc2cc1)C(=O)Nc1cc(cc(c1)C(=O)O)C(=O)O)c1cc(cnc1)C(=O)Nc1cc2ccc(cc2cc1)C(=O)Nc1cc(cc(c1)C(=O)O)C(=O)O | AL28: =9.98 -> 9.98 | AM28: =0.012 -> 0.012 | AY28: 0 | BA28: 0
A29: EBATUZ | B29: JLU-Liu29 | C29: http://dx.doi.org/10.1021/acs.cgd.6b01539 | D29: https://www.ccdc.cam.ac.uk/structures/Search?Ccdcid=EBATUZ&DatabaseToSearch=Published | E29: 8.26 | F29: 53.73 | G29: 7.3060317 | H29: 47.537107 | I29: autogenous | J29: 85 | K29: 24 | L29: 0.76 | M29: 22.99 | N29: DMF | O29: 3 | P29: 1 | Z29: CuI | AA29: 37 | AB29: =0.01*1000 -> 10 | AC29: =0.05 -> 0.05 | AD29: H4bdfdpa | AG29: 5-(6-(3,5-dicarboxylatephenyl)-s-indacen-2-yl)isophthalate | AH29: C(=O)(O)C=1C=C(C=C(C1)C(=O)O)C1=CC2=CC3=CC(=CC3=CC2=C1)C=1C=C(C=C(C(=O)O)C1)C(=O)O | AL29: =0.0024*1000 -> 2.4 | AM29: =0.005 -> 0.005 | AY29: 0 | BA29: 0
A30: PEWLUA | B30: NOTT-122 | C30: http://dx.doi.org/10.1039/C3SC21769H | D30: https://www.ccdc.cam.ac.uk/structures/Search?Ccdcid=PEWLUA&DatabaseToSearch=Published | E30: 8.26 | F30: 53.01 | G30: 7.4161116 | H30: 47.412118 | I30: autogenous | J30: 85 | K30: 18 | L30: 0.6 | M30: 149.4 | N30: DMF | O30: 3 | P30: =(5/6)*15 -> 12.5 | Q30: H2O | R30: 10 | S30: =(1/6)*15 -> 2.5 | T30: HCl | U30: 19 | V30: 2 | W30: 0.3 | X30: =V30*36.46/(1.18*1000) -> 0.06179661 | Y30: =W30*X30/Solvent!K20 -> 0.051497175 | Z30: Cu(NO₃)₂·2.5H₂O | AA30: 29 | AB30: =0.186*1000 -> 186 | AC30: =0.8 -> 0.8 | AD30: H6BTTI | AG30: 1,3,5-tris(1-(3,5-dicarboxyphenyl)-1H-1,2,3-triazol-4-yl)benzene | AH30: C(=O)(O)C=1C=C(C=C(C1)C(=O)O)N1N=NC(=C1)C1=CC(=CC(=C1)C=1N=NN(C1)C1=CC(=CC(=C1)C(=O)O)C(=O)O)C=1N=NN(C1)C1=CC(=CC(=C1)C(=O)O)C(=O)O | AL30: =0.1*1000 -> 100 | AM30: =0.13 -> 0.13 | AY30: 0 | BA30: 0
A31: SUKYIH | C31: http://dx.doi.org/10.1002/anie.200904983 | D31: https://www.ccdc.cam.ac.uk/structures/Search?Ccdcid=SUKYIH&DatabaseToSearch=Published | E31: 8.21 | F31: 53.62 | G31: 7.2513138 | H31: 47.153202 | I31: autogenous | J31: 80 | K31: 24 | L31: 0.72 | M31: 27.6 | N31: DEF | O31: 4 | P31: 4.5 | Q31: H2O | R31: 10 | S31: 1.5 | T31: HCl | U31: 19 | V31: 3 | W31: =0.5 -> 0.5 | X31: =V31*36.46/(1.18*1000) -> 0.092694915 | Y31: =W31*X31/Solvent!K20 -> 0.12874294 | Z31: Cu(NO₃)₂·2.5H₂O | AA31: 29 | AB31: 30 | AC31: =0.13 -> 0.13 | AD31: L1-H4 | AE31: 160248-28-2 | AF31: 4-[tris(4-carboxyphenyl)methyl]benzoate | AG31: ["tetrakis(4-Carboxyphenyl)methane", "4,4',4'',4'''-Methanetetrayltetrabenzoate"] | AH31: C(=O)(O)C1=CC=C(C=C1)C(C1=CC=C(C=C1)C(=O)O)(C1=CC=C(C=C1)C(=O)O)C1=CC=C(C=C1)C(=O)O | AI31: BLD Pharmatech GmbH | AJ31: 1 | AK31: 0.95 | AL31: 15 | AM31: =0.03 -> 0.03 | AX31: 144.5 | AY31: 2.1675 | BA31: 0
A32: HULCOI | C32: http://dx.doi.org/10.1016/j.poly.2015.06.001 | D32: https://www.ccdc.cam.ac.uk/structures/Search?Ccdcid=HULCOI&DatabaseToSearch=Published | E32: 8.09 | F32: 52.23 | G32: 7.2096656 | H32: 46.286346 | I32: autogenous | J32: 75 | K32: =3*24 -> 72 | L32: 0.2 | M32: 5 | N32: DMF | O32: 3 | P32: 15 | T32: HNO3 | U32: 16 | V32: 1 | W32: 0.5 | X32: =V32*63.02/(1.42*1000) -> 0.044380282 | Y32: =W32*X32/Solvent!K17 -> 0.03263256 | Z32: Cu(NO₃)₂·3H₂O | AA32: 30 | AB32: 19 | AC32: =0.075 -> 0.075 | AD32: H6-1 | AG32: 5,5',5''-(benzene-1,3,5-triyltris(carbamoylimino))triisophthalate | AH32: C1(=CC(=CC(=C1)N(C(N)=O)C=1C=C(C=C(C(=O)O)C1)C(=O)O)N(C(N)=O)C=1C=C(C=C(C(=O)O)C1)C(=O)O)N(C(N)=O)C=1C=C(C=C(C(=O)O)C1)C(=O)O | AL32: 20 | AM32: 0.027 | AY32: 0 | BA32: 0
A33: NAWXER | C33: http://dx.doi.org/10.1021/acs.cgd.7b00068 | D33: https://www.ccdc.cam.ac.uk/structures/Search?Ccdcid=NAWXER&DatabaseToSearch=Published | E33: 8.04 | F33: 58.16 | G33: 6.6119862 | H33: 47.835961 | I33: autogenous | J33: 85 | K33: 24 | L33: 0.5 | M33: =7.57*L33 -> 3.785 | N33: DMF | O33: 3 | P33: 1 | Q33: EtOH | R33: 12 | S33: 0.5 | T33: HNO3 | U33: 16 | V33: 2.7 | W33: =150/1000 -> 0.15 | X33: =V33*63.02/(1.42*1000) -> 0.11982676 | Y33: =W33*X33/Solvent!K17 -> 0.026432374 | Z33: Zn(NO₃)₂·6H₂O | AA33: 45 | AB33: 10 | AC33: 0.0336 | AD33: H4TCPP | AE33: 2089016-10-2 | AF33: 4-[3,5,6-tris(4-carboxyphenyl)pyrazin-2-yl]benzoate | AG33: ["4,4',4'',4'''-pyrazine-2,3,5,6-tetrabenzoate"] | AH33: C(=O)(O)C1=CC=C(C=C1)C=1C(=NC(=C(N1)C1=CC=C(C=C1)C(=O)O)C1=CC=C(C=C1)C(=O)O)C1=CC=C(C(=O)O)C=C1 | AI33: BLD Pharmatech GmbH | AJ33: 1 | AK33: 0.98 | AL33: 4 | AM33: 0.0071 | AX33: 82.45 | AY33: 0.3298 | BA33: 0
A34: RUVKAV | C34: http://dx.doi.org/10.1021/cg100046j | D34: https://www.ccdc.cam.ac.uk/structures/Search?Ccdcid=RUVKAV&DatabaseToSearch=Published | E34: 8.02 | F34: 52.47 | G34: 7.1989857 | H34: 46.790655 | I34: autogenous | J34: 70 | K34: 48 | L34: 0.91 | M34: =0.106*1000 -> 106 | N34: DMF | O34: 3 | P34: 4 | T34: HNO3 | U34: 16 | V34: 1 | W34: 0.7 | X34: =V34*63.02/(1.42*1000) -> 0.044380282 | Y34: =W34*X34/Solvent!K17 -> 0.045685584 | Z34: Cu(NO₃)₂·6H₂O | AA34: 32 | AB34: =0.034*1000 -> 34 | AC34: =0.16 -> 0.16 | AD34: H₃L₁ | AE34: 1239608-21-9 | AF34: 5-[4-(3,5-dicarboxyphenyl)buta-1,3-diynyl]benzene-1,3-dicarboxylate | AG34: ["5,5'-(Butadiyne-1,4-diyl)diisophthalate", "1,4-bis(3,5-Dicarboxylatephenyl)buta-1,3-diyne"] | AH34: C(#CC#CC=1C=C(C=C(C(=O)O)C1)C(=O)O)C=1C=C(C=C(C(=O)O)C1)C(=O)O | AI34: BLD Pharmatech GmbH | AJ34: 1 | AK34: 0.98 | AL34: =0.049*1000 -> 49 | AM34: =0.08 -> 0.08 | AX34: 393.55 | AY34: 19.28395 | BA34: 0
A35: FATQID | B35: JLU-Liu39 | C35: http://dx.doi.org/10.1039/C7DT00192D | D35: https://www.ccdc.cam.ac.uk/structures/Search?Ccdcid=FATQID&DatabaseToSearch=Published | E35: 8.01 | F35: 52.85 | G35: 7.2756556 | H35: 48.035145 | I35: autogenous | J35: 85 | K35: 24 | L35: 0.62 | M35: =9.12 -> 9.12 | N35: DMF | O35: 3 | P35: 2 | T35: HNO3 | U35: 16 | V35: 1 | W35: =0.05 -> 0.05 | X35: =V35*63.02/(1.42*1000) -> 0.044380282 | Y35: =W35*X35/Solvent!K17 -> 0.003263256 | Z35: CuSO₄·5H₂O | AA35: 33 | AB35: 8 | AC35: =0.03 -> 0.03 | AD35: H₂L | AE35: 171820-04-5 | AF35: 3,5-bis(4-carboxylatophenyl)pyridine | AG35: ["3,5-bis(4-carboxylatephenyl)pyridine"] | AH35: C(=O)(O)C1=CC=C(C=C1)C=1C=NC=C(C1)C1=CC=C(C=C1)C(=O)O | AI35: XtalPi Inc | AJ35: 1 | AK35: 0.95 | AL35: =5 -> 5 | AM35: =0.015 -> 0.015 | AX35: 30.43 | AY35: 0.15215 | BA35: 0
A36: NUBPIL | C36: http://dx.doi.org/10.1039/C4DT03371J | D36: https://www.ccdc.cam.ac.uk/structures/Search?Ccdcid=NUBPIL&DatabaseToSearch=Published | E36: 7.87 | F36: 52.02 | G36: 7.0942647 | H36: 46.805767 | I36: autogenous | J36: 80 | K36: 48 | L36: 0.67 | M36: 18 | N36: DMF | O36: 3 | P36: 10 | T36: HCl | U36: 19 | V36: 0.1 | W36: 0.6 | X36: =V36*36.46/(1.18*1000) -> 0.0030898305 | Y36: =W36*X36/Solvent!K20 -> 0.0051497175 | Z36: CuCl₂·2H₂O | AA36: 34 | AB36: 10 | AC36: 0.06 | AD36: H₂L | AE36: 1643586-52-0 | AF36: 5-(1H-imidazole-1-yl)benzene-1,3-dicarboxylate | AG36: ["5-(1H-Imidazol-1-yl)isophthalate"] | AH36: N1(C=NC=C1)C=1C=C(C=C(C(=O)O)C1)C(=O)O | AI36: AmBeed | AJ36: 1 | AK36: 0.98 | AL36: 10 | AM36: 0.04 | AX36: 100.62 | AY36: 1.0062 | BA36: 0
A37: ADASUV | B37: rht-MOF-4c | C37: http://dx.doi.org/10.1002/anie.201201202 | D37: https://www.ccdc.cam.ac.uk/structures/Search?Ccdcid=ADASUV&DatabaseToSearch=Published | E37: 7.77 | F37: 52.74 | G37: 6.8633804 | H37: 46.858834 | I37: autogenous | J37: =(85+105)/2 -> 95 | K37: =12+23 -> 35 | L37: 0.5 | M37: =41*L37 -> 20.5 | N37: DMF | O37: 3 | P37: 1 | Q37: NMP | R37: 5 | S37: 0.5 | Z37: Co(NO₃)₂·6H₂O | AA37: 41 | AB37: 24 | AC37: =0.0825 -> 0.0825 | AD37: H₆tL₁ | AG37: 5,5',5''-(Benzene-1,3,5-triyltris(methyleneoxy))-tri-isophthalate | AH37: C1(=CC(=CC(=C1)COC=1C=C(C=C(C(=O)O)C1)C(=O)O)COC=1C=C(C=C(C(=O)O)C1)C(=O)O)COC=1C=C(C=C(C(=O)O)C1)C(=O)O | AL37: 37 | AM37: =0.056 -> 0.056 | AY37: 0 | BA37: 0
A38: ENESOH | B38: 1 | C38: http://dx.doi.org/10.1039/C6CE01035K | D38: https://www.ccdc.cam.ac.uk/structures/Search?Ccdcid=ENESOH&DatabaseToSearch=Published | E38: 7.74 | F38: 53.61 | G38: 6.6834784 | H38: 46.137398 | I38: autogenous | J38: 85 | K38: =4*24 -> 96 | L38: 0.34 | M38: 54.94 | N38: H2O | O38: 10 | P38: 5 | Q38: MeOH | R38: 11 | S38: 5 | Z38: CuCl₂·2H₂O | AA38: 34 | AB38: =0.085*1000 -> 85 | AC38: =0.5 -> 0.5 | AD38: TAAP | AF38: N-pyridin-3-yl-2-(tetrazol-1-yl)acetamide | AG38: ["N-(pyridin-3-yl)-2-(1H-tetrazol-1-yl)acetamide"] | AH38: N1=CC(=CC=C1)NC(CN1N=NN=C1)=O | AI38: Enamine | AJ38: 0.05 | AK38: 0.9 | AL38: =0.02*1000 -> 20 | AM38: =0.1 -> 0.1 | AN38: (NH₄)₆Mo₇O₂₄·4H₂O | AV38: =0.124*1000 -> 124 | AW38: =0.1 -> 0.1 | AX38: 4558 | AY38: 91.16 | AZ38: 0.84466226 | BA38: 0.10473812
A39: ADASOP | B39: rht-MOF-4b | C39: http://dx.doi.org/10.1002/anie.201201202 | D39: https://www.ccdc.cam.ac.uk/structures/Search?Ccdcid=ADASOP&DatabaseToSearch=Published | E39: 7.7 | F39: 52.7 | G39: 6.8413301 | H39: 46.573655 | I39: autogenous | J39: 85 | K39: 12 | L39: 0.5 | M39: =19.4*L39 -> 9.7 | N39: DMF | O39: 3 | P39: 1 | Q39: NMP | R39: 5 | S39: 1 | Z39: Zn(NO₃)₂·6H₂O | AA39: 45 | AB39: 12.5 | AC39: =0.042 -> 0.042 | AD39: H₆tL₁ | AE39: 98036-00-1 | AG39: 5,5',5''-(Benzene-1,3,5-triyltris(methyleneoxy))-tri-isophthalate | AH39: C1(=CC(=CC(=C1)COC=1C=C(C=C(C(=O)O)C1)C(=O)O)COC=1C=C(C=C(C(=O)O)C1)C(=O)O)COC=1C=C(C=C(C(=O)O)C1)C(=O)O | AI39: BLD Pharmatech GmbH | AJ39: 1 | AK39: 0.99 | AL39: 18 | AM39: =0.0273 -> 0.0273 | AX39: 260.1 | AY39: 4.6818 | BA39: 0
A40: ZIQJEQ | B40: 3 | C40: http://dx.doi.org/10.1002/asia.201301378 | D40: https://www.ccdc.cam.ac.uk/structures/Search?Ccdcid=ZIQJEQ&DatabaseToSearch=Published | E40: 7.63 | F40: 51.98 | G40: 6.7161915 | H40: 45.646927 | I40: autogenous | J40: 140 | K40: =5*24 -> 120 | L40: 0.4 | M40: 284 | N40: H2O | O40: 10 | P40: 10 | Z40: Cu(NO₃)₂·6H₂O | AA40: 32 | AB40: 236 | AC40: =0.8 -> 0.8 | AD40: BBTZ | AE40: 143131-66-2 | AF40: 1,1'-(1,4-phenylenebis(methylene))bis(1H-1,2,4-triazole) | AG40: ["1,4-bis(1,2,4-triazol-1-ylmethyl)benzene", "1,1'-(1,4-phenylenebis(methylene))bis(1H-1,2,4-triazole)"] | AH40: C1(=CC=C(C=C1)CN1N=CN=C1)CN1N=CN=C1 | AI40: XtalPi Inc | AJ40: 1 | AK40: 0.95 | AL40: 150 | AM40: 0.625 | AV40: 500 | AW40: 0.2 | AX40: 15.164 | AY40: 2.2746 | BA40: 0
...

Sheet Solvent
A1: Solvent | B1: Solvent_Code | C1: Solvent_CAS | D1: Vendor_Name_Analytical_Grade | E1: Max_Amount_Analytical_Grade (L) | F1: Min_Purity_Analytical_Grade | G1: Rel_Price_Analytical_Grade (€/ml) | H1: Rel_Price_Analytical_Grade (Rp./ml) | I1: Vendor_Name_Technical_Grade | J1: Max_Amount_Technical_Grade (L) | K1: Min_Purity_Technical_Grade | L1: Rel_Price_Technical_Grade (€/ml) | M1: Rel_Price_Technical_Grade (Rp./ml)
A2: DEA | B2: 0 | C2: 91-66-7 | D2: Sigma Aldrich | E2: 1 | F2: 0.99 | G2: 0.079959514 | H2: 1501 | I2: PT Graha Jaya Pratama Kinerja | J2: 215.14312 | K2: 0.85 | L2: 0.002075685 | M2: 39.153232
A3: DMA | B3: 1 | C3: 127-19-5 | D3: Sigma Aldrich | E3: 8 | F3: 0.999 | G3: 0.22858513 | H3: 4291 | I3: Trimax Chemicals | J3: 52.301255 | K3: 0.98 | L3: 0.0019610143 | M3: 36.99022
A4: DMAc | B4: 2 | C4: 127-19-5 | D4: Sigma Aldrich | E4: 8 | F4: 0.999 | G4: 0.22858513 | H4: 4291 | I4: Trimax Chemicals | J4: 52.301255 | K4: 0.98 | L4: 0.0019610143 | M4: 36.99022
A5: DMF | B5: 3 | C5: 68-12-2 | D5: Sigma Aldrich | E5: 200 | F5: 0.998 | G5: 0.17472832 | H5: 3280 | I5: Trimax Chemicals | J5: 200 | K5: 0.99 | L5: 0.00065367143 | M5: 12.330073
A6: DEF | B6: 4 | C6: 68-84-2 | D6: Sigma Aldrich | E6: 0.11013216 | F6: 0.99 | G6: 1.0230237 | H6: 19204.2 | I6: Lonwin Industry Group Limited Co., Ltd. | J6: 220.26432 | K6: 0.99 | L6: 0.00039147778 | M6: 7.384367
A7: NMP | B7: 5 | C7: 872-50-4 | D7: Sigma Aldrich | E7: 18 | F7: 0.99 | G7: 0.16695078 | H7: 3134 | I7: Jigs Chemical | K7: 0.99 | L7: 0.0017342101 | M7: 32.712058
A8: DMSO | B8: 6 | C8: 67-68-5 | D8: Sigma Aldrich | E8: 18 | F8: 0.999 | G8: 0.29501385 | H8: 5538 | I8: Jiangsu Juming Chemical Technology Co., Ltd. | J8: 22.727273 | K8: 0.99 | L8: 0.00047425722 | M8: 8.9458191
A9: DMPU | B9: 7 | C9: 2687-91-4 | D9: Sigma Aldrich | E9: 0.47169811 | F9: 0.98 | G9: 0.80183252 | H9: 15052 | I9: Otto Chemie pvt ltd | K9: 0.98 | L9: 0.21414383 | M9: 4039.3523
A10: HFP | B10: 8 | C10: 920-66-1 | D10: Sigma Aldrich | E10: 0.31328321 | F10: 0.99 | G10: 4.1617409 | H10: 78124.2 | I10: Jinan Qinmu Fine Chemical Co., Ltd. | J10: 15.66416 | K10: 0.99 | L10: 0.0013762082 | M10: 25.95914
A11: NaOH | B11: 9 | C11: 1310-73-2 | D11: Sigma Aldrich | E11: 0.5 | F11: 0,9-1,1 M | G11: 1.0110803 | H11: 18980 | I11: HK Chemicals | J11: 11.737089 | K11: 0.99 | L11: 0.0021104837 | M11: 39.809632
A12: H2O | B12: 10 | C12: 7732-18-5 | D12: Sigma Aldrich | E12: 20 | G12: 0.083848285 | H12: 1574 | I12: Mika Chemical | J12: 200 | K12: 0.99 | L12: 0.00019044321 | M12: 3.5922922
A13: MeOH | B13: 11 | C13: 67-56-1 | D13: Sigma Aldrich | E13: 20 | F13: 0.998 | G13: 0.080652035 | H13: 1514 | I13: PT. Anugrah Putra Kencana | J13: 200 | K13: 0.99 | L13: 0.0003728958 | M13: 7.0338589
A14: EtOH | B14: 12 | C14: 64-17-5 | D14: Sigma Aldrich | E14: 20 | F14: 0.995 | G14: 0.21372257 | H14: 4012 | I14: Trimax Chemicals | K14: 0.999 | L14: 0.00058434264 | M14: 11.022338
A15: Cellosolve | B15: 13 | C15: 110-80-5 | D15: Sigma Aldrich | E15: 2.5 | F15: 0.98 | G15: 0.06040912 | H15: 1134 | I15: Shubham Fine Chem | J15: 200 | K15: 0.999 | L15: 0.00089137013 | M15: 16.813736
A16: MeCN | B16: 14 | C16: 75-05-8 | D16: Sigma Aldrich | E16: 20 | F16: 0.995 | G16: 0.15560409 | H16: 2921 | I16: Shandong Dexiang International Trade Co.,Ltd | J16: 203.56234 | K16: 0.999 | L16: 0.00033887834 | M16: 6.3921943
A17: HNO3 | B17: 16 | C17: 7697-37-2 | D17: Sigma Aldrich | E17: 2.5 | F17: 0.7 | G17: 0.071894311 | H17: 1349.6 | I17: KEY Chemicals | K17: 0.68 | L17: 0.0016641807 | M17: 31.391108
A18: NH3 | B18: 17 | C18: 7664-41-7 | D18: Sigma Aldrich | E18: 1 | F18: 4 M in MeOH | G18: 0.75713829 | H18: 14213 | I18: Om Sai Enterprises | K18: 0.25 | L18: 0.00014856169 | M18: 2.8022894
A19: HBF4 | B19: 18 | C19: 16872-11-0 | D19: Sigma Aldrich | E19: 0.35714286 | F19: 48% in H2O | G19: 0.44001705 | H19: 8260 | I19: Jay Unnati Chem | J19: 200 | K19: 0.99 | L19: 0.00059424675 | M19: 11.209158
A20: HCl | B20: 19 | C20: 7647-01-0 | D20: Sigma Aldrich | E20: 12 | F20: 0.37 | G20: 0.041626714 | H20: 781.41667 | I20: Qingdao Langyi Industrial Co.,Ltd | J20: 215.51724 | K20: 0.36 | L20: 0.00013003271 | M20: 2.4527809
A21: H3PMo12O40 | B21: 20 | C21: 12501-23-4 | D21: Sigma Aldrich | G21: 0.041626714 | H21: 781.41667 | I21: Hebei Kenbin Technology Co.,Ltd | J21: 15.432099 | K21: 0.999 | L21: 0.013969031 | M21: 263.49503
A22: AcOH | B22: 21 | C22: 64-19-7 | D22: Sigma Aldrich | E22: 18 | F22: 0.99 | G22: 0.034164358 | H22: 641.33333 | I22: Hebei Jinchangsheng Chemical Technology Co.,Ltd | J22: 204.9571 | K22: 0.9985 | L22: 0.00036181514 | M22: 6.8248467
A23: Triethylamine | B23: 22 | C23: 121-44-8 | D23: Sigma Aldrich | E23: 3 | F23: 0.995 | G23: 0.16485546 | H23: 3094.6667 | I23: Inner Mongolia Harbor Trade Chemicals Co.,Ltd | J23: 192.83747 | K23: 0.995 | L23: 0.00087642734 | M23: 16.531874
A24: EG | B24: 23 | C24: 107-21-1 | D24: Sigma Aldrich | E24: 6 | F24: 0.998 | G24: 0.1202145 | H24: 2256.6667 | I24: Inner Mongolia Harbor Trade Chemicals Co.,Ltd | J24: 204.91803 | K24: 0.995 | L24: 0.002430094 | M24: 45.838377
A25: CH3ONa | B25: 24 | C25: 124-41-4 | D25: Sigma Aldrich | E25: 2.5 | F25: 25% in MeOH | G25: 0.038866397 | H25: 729.6 | I25: Weihai Jindo Chemical Co.,Ltd | J25: 206.18557 | K25: 0.99 | L25: 0.00066913382 | M25: 12.621737
A26: Dioxane | B26: 25 | C26: 123-91-1 | D26: Sigma Aldrich | E26: 2 | F26: 0.99 | G26: 0.11668975 | H26: 2190.5 | I26: Shandong Dexiang International Trade Co.,Ltd | K26: 0.99 | L26: 0.00044580179 | M26: 8.4090699
A27: 1,4-dioxane | B27: 26 | C27: 123-91-1 | D27: Sigma Aldrich | E27: 2 | F27: 0.99 | G27: 0.11668975 | H27: 2190.5 | I27: Shandong Dexiang International Trade Co.,Ltd | K27: 0.99 | L27: 0.00044580179 | M27: 8.4090699
A28: CH2Cl2 | B28: 27 | C28: 75-09-2 | D28: Sigma Aldrich | E28: 8 | F28: 0.998 | G28: 0.095021841 | H28: 1783.75 | I28: Zibo Aiheng New Material Co.,Ltd | J28: 203.77358 | K28: 0.995 | L28: 0.0004570115 | M28: 8.6205165

Sheet Metal
A1: Metal | B1: Num_Hidrate | C1: Metal_Code | D1: Metal_CAS | E1: Vendor_Name_Analytical_Grade | F1: Max_Amount_Analytical_Grade (g) | G1: Min_Purity_Analytical_Grade | H1: Rel_Price_Analytical_Grade (€/g) | I1: Rel_Price_Analytical_Grade (Rp./g) | J1: Vendor_Name_Technical_Grade | K1: Max_Amount_Technical_Grade (g) | L1: Min_Purity_Technical_Grade | M1: Rel_Price_Technical_Grade (€/g) | N1: Rel_Price_Technical_Grade (Rp./g)
A2: Cu(NO₃)₂ | B2: 2 | C2: 28 | D2: 19004-19-3 | E2: Sigma Aldrich | F2: 500 | G2: 0.98 | H2: 0.44619646 | I2: 8376 | J2: W&Q Fine Chemicals | K2: 25000 | L2: 0.99 | M2: 0.00255 | N2: 48.10014
B3: 2.5 | C3: 29 | D3: 19004-19-4 | E3: Sigma Aldrich | F3: 500 | G3: 0.98 | H3: 0.44619646 | I3: 8376 | J3: W&Q Fine Chemicals | K3: 25000 | L3: 0.99 | M3: 0.00255 | N3: 48.10014
B4: 3 | C4: 30 | D4: 10031-43-3 | E4: Sigma Aldrich | F4: 100 | G4: 0.99 | H4: 1.1288089 | I4: 21190 | J4: W&Q Fine Chemicals | K4: 25000 | L4: 0.99 | M4: 0.00255 | N4: 48.10014
B5: 4 | C5: 31 | D5: 13478-38-1 | E5: Sigma Aldrich | F5: 50 | G5: 0.98 | H5: 1.6383431 | I5: 30754.977 | J5: W&Q Fine Chemicals | K5: 25000 | L5: 0.99 | M5: 0.00255 | N5: 48.10014
B6: 6 | C6: 32 | D6: 13778-31-9 | E6: Sigma Aldrich | F6: 100 | G6: 0.98 | H6: 3.1214748 | I6: 58596.325 | J6: W&Q Fine Chemicals | K6: 25000 | L6: 0.99 | M6: 0.00255 | N6: 48.10014
A7: CuSO₄ | B7: 5 | C7: 33 | D7: 7758-99-8 | E7: Sigma Aldrich | F7: 25000 | G7: 0.98 | H7: 0.066605583 | I7: 1250.32 | J7: Hebei Pusuo Import & Export Co., Ltd. | K7: 25000 | L7: 0.99 | M7: 0.00051 | N7: 9.620028
A8: CuCl₂ | B8: 2 | C8: 34 | D8: 10125-13-0 | E8: Sigma Aldrich | F8: 500 | G8: 0.99 | H8: 0.66524611 | I8: 12488 | J8: W&Q Fine Chemicals | K8: 25000 | L8: 0.99 | M8: 0.0034 | N8: 64.13352
B9: 3 | C9: 35 | D9: 10025-89-3 | E9: Sigma Aldrich | F9: 500 | G9: 0.99 | H9: 0.66524611 | I9: 12488 | J9: W&Q Fine Chemicals | K9: 25000 | L9: 0.99 | M9: 0.0034 | N9: 64.13352
A10: Cu(BF₄)₂ | B10: 6 | C10: 36 | D10: 207121-39-9 | E10: Sigma Aldrich | F10: 250 | G10: 0.22 | H10: 0.83571276 | I10: 15688 | J10: AB Enterprises | L10: 0.99 | M10: 0.0099041125 | N10: 186.81929
A11: CuI | C11: 37 | D11: 7681-65-4 | E11: TCI Chemicals | F11: 500 | G11: 0.98 | H11: 0.23109261 | I11: 4338.0704 | J11: Jiangsu Juming Chemical Technology Co., Ltd. | K11: 25000 | L11: 0.99 | M11: 0.00425 | N11: 80.1669
A12: Cu(OAc)₂ | B12: 1 | C12: 38 | D12: 142-71-2 | E12: Sigma Aldrich | F12: 100 | G12: 0.98 | H12: 2.6049435 | I12: 48900 | J12: Shandong Shengbang Import and Export Co., Ltd. | L12: 0.99 | M12: 0.000425 | N12: 8.01669
A13: CuBr₂ | C13: 39 | D13: 7789-45-9 | E13: Sigma Aldrich | F13: 500 | G13: 0.99 | H13: 0.53473258 | I13: 10038 | J13: Suzhou Senfeida Chemical Co., Ltd. | K13: 25000 | L13: 0.99 | M13: 0.0085 | N13: 160.3338
A14: Cu(ClO₄)₂ | B14: 6 | C14: 40 | D14: 10294-46-9 | E14: TCI Chemicals | F14: 250 | G14: 0.95 | H14: 0.76226069 | I14: 14309.158 | J14: Chem Lab | L14: 0.99 | M14: 0.0022086171 | N14: 41.660702
A15: Co(NO₃)₂ | B15: 6 | C15: 41 | D15: 10026-22-9 | E15: Thermo Fisher | F15: 500 | G15: 0.99 | H15: 0.34775988 | I15: 6528.1485 | J15: Hainan Xinda Chuancheng Petrochemical Co., Ltd. | K15: 10000 | L15: 0.99 | M15: 0.0085 | N15: 160.3338
A16: Co(ClO₄)₂ | B16: 6 | C16: 42 | D16: 13478-20-1 | E16: Fisher Scientific | F16: 250 | G16: 0.99 | H16: 0.77829921 | I16: 14610.233 | J16: Chem Lab | L16: 0.98 | M16: 0.001852069 | N16: 34.935208
A17: CoSO₄ | B17: 7 | C17: 43 | D17: 10026-24-1 | E17: Sigma Aldrich | F17: 2500 | G17: 0.99 | H17: 0.21035585 | I17: 3948.8 | J17: W&Q Fine Chemicals | K17: 25000 | L17: 0.99 | M17: 0.00425 | N17: 80.1669
A18: Zn(NO₃)₂ | B18: 4 | C18: 44 | D18: 19154-63-3 | E18: Phytotech Lab | F18: 500 | G18: 0.98 | H18: 0.10399167 | I18: 1952.1317 | J18: JK Chemicals | K18: 50000 | L18: 0.99 | M18: 0.00084184956 | N18: 15.87964
B19: 6 | C19: 45 | D19: 10196-18-6 | E19: Sigma Aldrich | F19: 500 | G19: 0.98 | H19: 0.21287023 | I19: 3996 | J19: Goyal Chem Associates | K19: 50000 | L19: 0.98 | M19: 0.0012875346 | N19: 24.286508
A20: Zn(CH₃COO)₂ | B20: 2 | C20: 46 | D20: 5970-45-6 | E20: Sigma Aldrich | F20: 2500 | G20: 0.98 | H20: 0.16309397 | I20: 3061.6 | J20: W&Q Fine Chemicals | K20: 25000 | L20: 0.99 | M20: 0.0023715 | N20: 44.73313
A21: ZnCl₂ | C21: 47 | D21: 7646-85-7 | E21: Sigma Aldrich | F21: 1000 | G21: 0.98 | H21: 0.21265715 | I21: 3992 | J21: Shandong Dexiang International Trade Co., Ltd. | L21: 0.99 | M21: 0.000425 | N21: 8.01669
A22: Ni(NO₃)₂ | B22: 6 | C22: 48 | D22: 13478-00-7 | E22: Sigma Aldrich | F22: 250 | G22: 0.97 | H22: 0.33198381 | I22: 6232 | J22: Zhengzhou Delong Chemical Co., Ltd. | K22: 50000 | L22: 0.99 | M22: 0.002125 | N22: 40.08345
B23: 7 | C23: 49 | D23: 13478-00-7 | E23: Sigma Aldrich | F23: 250 | G23: 0.97 | H23: 0.33198381 | I23: 6232 | J23: Zhengzhou Delong Chemical Co., Ltd. | K23: 50000 | L23: 0.99 | M23: 0.002125 | N23: 40.08345
A24: Mn(NO₃)₂ | B24: 4 | C24: 50 | D24: 13446-34-9 | E24: Alfa Aesar | F24: 1000 | G24: 0.98 | H24: 0.20005032 | I24: 3755.3446 | J24: SV Trading Company | L24: 0.99 | M24: 0.0013865758 | N24: 26.154701
A25: MnCl₂ | B25: 4 | C25: 51 | D25: 13446-34-9 | E25: Sigma Aldrich | F25: 500 | G25: 0.98 | H25: 0.36639676 | I25: 6878 | J25: Ningbo Surest Chemical Co., Ltd. | K25: 25000 | M25: 0.0068 | N25: 128.26704
A26: Cd(NO₃)₂ | B26: 4 | C26: 52 | D26: 10022-68-1 | E26: Sigma Aldrich | F26: 500 | G26: 0.98 | H26: 0.55636054 | I26: 10444 | J26: Zama Chemical | M26: 0.000792329 | N26: 14.945543
B27: 6 | C27: 53 | D27: 10022-68-1 | E27: Sigma Aldrich | F27: 500 | G27: 0.98 | H27: 0.55636054 | I27: 10444 | J27: Zama Chemical | M27: 0.000792329 | N27: 14.945543
A28: CdSO₄ | B28: 8 | C28: 54 | D28: 7790-84-3 | E28: Neofroxx | F28: 500 | G28: 0.98 | H28: 0.21362834 | I28: 4010.2313 | J28: Zama Chemical | M28: 0.0011884935 | N28: 22.418315
A29: Cd(CH₃COO)₂ | B29: 2 | C29: 55 | D29: 5743-04-4 | E29: Sigma Aldrich | F29: 500 | G29: 0.98 | H29: 0.77839335 | I29: 14612 | J29: The Truth Labs | K29: 5000 | L29: 0.99 | M29: 0.00099041125 | N29: 18.681929
A30: Cd(ClO₄)₂ | B30: 6 | C30: 56 | D30: 10326-27-9 | E30: Reagents.com | F30: 250 | G30: 0.99 | H30: 1.0071499 | I30: 18906.217 | J30: Chem lab | L30: 0.99 | M30: 0.001852069 | N30: 34.935208
A31: Mg(NO₃)₂ | B31: 6 | C31: 57 | D31: 13446-18-9 | E31: Sigma Aldrich | F31: 2500 | G31: 0.99 | H31: 0.14331984 | I31: 2690.4 | J31: NRS Chemicals LLP | L31: 0.99 | M31: 0.0006338632 | N31: 11.956435
A32: LiOH | C32: 58 | D32: 1310-65-2 | E32: Sigma Aldrich | F32: 500 | G32: 0.98 | H32: 0.7043469 | I32: 13222 | J32: Jinan Future Chemical Co., Ltd. | K32: 25000 | L32: 0.99 | M32: 0.00425 | N32: 80.1669
